Workbook

Sheet Summary
A1: Database D — original vs final file
A2: Original: database_D_old_format.txt. Final: database_D_merged.txt minus the 8 duplicate rows deleted afterwards. All values below are formulas over the other sheets.
A4: Assumption | B4: Value | C4: Note
A5: Threshold for a notable change in M, R or Teff | B5: 0.03 | C5: Editable. Drives 'Replaced rows' column U and the highlighted Δ cells.
A7: Counts | B7: Value | C7: Note
A8: Rows in original file | B8: =COUNT('Seq map'!D:D) -> 13696 | C8: All are in the final file except the deleted duplicates below
A9: Rows in final file | B9: =COUNT('Seq map'!A:A)-COUNTIF('Seq map'!C:C,"Deleted") -> 13719
A10: Untouched rows (identical except Seq) | B10: =COUNTIF('Seq map'!C:C,"Untouched") -> 13659
A11: Replaced rows | B11: =COUNTIF('Seq map'!C:C,"Replaced") -> 31 | C11: See 'Replaced rows'
A12: Added rows | B12: =COUNTIF('Seq map'!C:C,"Added") -> 29 | C12: See 'Added rows'
A13: Deleted rows (same star under another name) | B13: =COUNTIF('Seq map'!C:C,"Deleted") -> 8 | C13: See 'Deleted rows'
A14: … from the original file | B14: =COUNTIF('Deleted rows'!C:C,"Original file") -> 6 | C14: TIC 37606218, TIC 138857475, TIC 287841093
A15: … from the update file | B15: =COUNTIF('Deleted rows'!C:C,"Update file") -> 2 | C15: CPD-54 810
A16: Original IDs replaced under a new name | B16: =COUNTIF('Replaced rows'!F:F,"Yes") -> 11 | C16: Same stars, now under the update's name
A17: Rows that kept their ID | B17: =SUMPRODUCT(('Seq map'!F2:F13728<>"")*('Seq map'!C2:C13728<>"Deleted")) -> 13679
A18: … of which have a different Seq (Seq as in merged file) | B18: =COUNTIF('Seq map'!G:G,"Yes") -> 13610 | C18: The original numbering skipped values. Remap anything keyed on the old Seq with 'Seq map'
A19: … of which have a different Seq (if renumbered after deletions) | B19: =SUMPRODUCT(('Seq map'!F2:F13728<>"")*('Seq map'!C2:C13728<>"Deleted")*('Seq map'!F2:F13728<>'Seq map'!H2:H13728)) -> 13653 | C19: Use 'Seq map' column H in that case
A20: Replaced rows with an M, R or Teff change above the threshold | B20: =COUNTIF('Replaced rows'!U:U,"Yes") -> 6
A21: Replaced rows whose source (catalog) changed | B21: =SUMPRODUCT(--('Replaced rows'!G2:G32<>'Replaced rows'!H2:H32)) -> 23
A22: Changed cells in replaced rows | B22: =COUNT('Cell changes'!A:A) -> 528 | C22: See 'Cell changes'
A23: … value changed | B23: =COUNTIF('Cell changes'!G:G,"changed") -> 437
A24: … filled where the original had NA | B24: =COUNTIF('Cell changes'!G:G,"filled") -> 91
A25: Newly filled: oblateness | B25: =COUNTIFS('Cell changes'!D:D,"oblateness",'Cell changes'!G:G,"filled") -> 13 | C25: Stars
A26: Newly filled: orbit_a | B26: =COUNTIFS('Cell changes'!D:D,"orbit_a",'Cell changes'!G:G,"filled") -> 11 | C26: Stars
A27: Newly filled: Meta | B27: =COUNTIFS('Cell changes'!D:D,"Meta",'Cell changes'!G:G,"filled") -> 6 | C27: Stars
A28: Newly filled: logg | B28: =COUNTIFS('Cell changes'!D:D,"logg",'Cell changes'!G:G,"filled") -> 3 | C28: Stars
A29: Newly filled: detached | B29: =COUNTIFS('Cell changes'!D:D,"detached",'Cell changes'!G:G,"filled") -> 3 | C29: Stars
A30: Spectral type changed | B30: =COUNTIF('Cell changes'!D:D,"type") -> 13 | C30: Mostly more specific (e.g. F → F8V); see LL Aqr note
A31: New systems added | B31: =SUMPRODUCT(('Added rows'!D2:D30="New system")/COUNTIF('Added rows'!C2:C30,'Added rows'!C2:C30)) -> 13
A32: … rows from new systems | B32: =COUNTIF('Added rows'!D:D,"New system") -> 26
A33: Companions of systems already in the file | B33: =COUNTIF('Added rows'!D:D,"Companion of a system already in the file") -> 3 | C33: KIC10001167_B, KIC5640750_A, KIC8410637_A
A35: Renamed systems: original | B35: → | C35: Final
A36: TIC28051929 | B36: → | C36: HD4875
A37: TIC278683641 | B37: → | C37: TYC_8547-22-1
A38: BEPOP-3 | B38: → | C38: TYC_4535-148-1
A39: KIC10001167 | B39: → | C39: KIC10001167_A
A40: Cl*_NGC_188_KS_V12 | B40: → | C40: V785_Cep
A41: KIC_6131659 | B41: → | C41: KIC6131659
A43: Notes
A44: A/B letters swapped between files: AI Phe and KIC 9540226.
...

Sheet Replaced rows
A1: Seq in merged file | B1: Final ID | C1: Original Seq | D1: Original ID | E1: Match | F1: Original ID gone from final | G1: Catalog (original) | H1: Catalog (final) | I1: M original (Msun) | J1: M final (Msun) | K1: ΔM | L1: R original (Rsun) | M1: R final (Rsun) | N1: ΔR | O1: Teff original (K) | P1: Teff final (K) | Q1: ΔTeff | R1: Meta original (dex) | S1: Meta final (dex) | T1: ΔMeta (dex) | U1: Above threshold | V1: Newly filled (was NA) | W1: Other label changes
A2: 27 | B2: HD4875_A | C2: 27 | D2: TIC28051929_A | E2: By parameters: different name | F2: =IF(SUMPRODUCT(--('Seq map'!$B$2:$B$13728=D2))=0,"Yes","No") -> Yes | G2: CakirliDec25 | H2: Hahlin26 | I2: 1.088 | J2: 1.115 | K2: =IF(OR(I2="",J2=""),"",J2/I2-1) -> 0.024816176 | L2: 1.285 | M2: 1.295 | N2: =IF(OR(L2="",M2=""),"",M2/L2-1) -> 0.0077821012 | O2: 5985 | P2: 6013 | Q2: =IF(OR(O2="",P2=""),"",P2/O2-1) -> 0.0046783626 | S2: 0.119 | T2: =IF(OR(R2="",S2=""),"",S2-R2) | U2: =IF(MAX(IFERROR(ABS(K2),0),IFERROR(ABS(N2),0),IFERROR(ABS(Q2),0))>Threshold,"Yes","") | V2: Meta | W2: type F/G → G3V
A3: 28 | B3: HD4875_B | C3: 28 | D3: TIC28051929_B | E3: By parameters: different name | F3: =IF(SUMPRODUCT(--('Seq map'!$B$2:$B$13728=D3))=0,"Yes","No") -> Yes | G3: CakirliDec25 | H3: Hahlin26 | I3: 0.432 | J3: 0.4405 | K3: =IF(OR(I3="",J3=""),"",J3/I3-1) -> 0.019675926 | L3: 0.4133 | M3: 0.4209 | N3: =IF(OR(L3="",M3=""),"",M3/L3-1) -> 0.01838858 | O3: 3581 | P3: 3425 | Q3: =IF(OR(O3="",P3=""),"",P3/O3-1) -> -0.04356325 | S3: 0.119 | T3: =IF(OR(R3="",S3=""),"",S3-R3) | U3: =IF(MAX(IFERROR(ABS(K3),0),IFERROR(ABS(N3),0),IFERROR(ABS(Q3),0))>Threshold,"Yes","") -> Yes | V3: Meta
A4: 37 | B4: TYC_8547-22-1_A | C4: 37 | D4: TIC278683641_A | E4: By parameters: different name | F4: =IF(SUMPRODUCT(--('Seq map'!$B$2:$B$13728=D4))=0,"Yes","No") -> Yes | G4: CakirliDec25 | H4: Hahlin26 | I4: 1.273 | J4: 1.2908 | K4: =IF(OR(I4="",J4=""),"",J4/I4-1) -> 0.013982718 | L4: 1.612 | M4: 1.6391 | N4: =IF(OR(L4="",M4=""),"",M4/L4-1) -> 0.016811414 | O4: 5940 | P4: 5995 | Q4: =IF(OR(O4="",P4=""),"",P4/O4-1) -> 0.0092592593 | R4: 0.2907 | S4: 0.22 | T4: =IF(OR(R4="",S4=""),"",S4-R4) -> -0.0707 | U4: =IF(MAX(IFERROR(ABS(K4),0),IFERROR(ABS(N4),0),IFERROR(ABS(Q4),0))>Threshold,"Yes","") | W4: type F/G → G0
A5: 38 | B5: TYC_8547-22-1_B | C5: 38 | D5: TIC278683641_B | E5: By parameters: different name | F5: =IF(SUMPRODUCT(--('Seq map'!$B$2:$B$13728=D5))=0,"Yes","No") -> Yes | G5: CakirliDec25 | H5: Hahlin26 | I5: 0.589 | J5: 0.5891 | K5: =IF(OR(I5="",J5=""),"",J5/I5-1) -> 0.00016977929 | L5: 0.585 | M5: 0.58966 | N5: =IF(OR(L5="",M5=""),"",M5/L5-1) -> 0.007965812 | O5: 3653 | P5: 3552 | Q5: =IF(OR(O5="",P5=""),"",P5/O5-1) -> -0.027648508 | R5: 0.2907 | S5: 0.22 | T5: =IF(OR(R5="",S5=""),"",S5-R5) -> -0.0707 | U5: =IF(MAX(IFERROR(ABS(K5),0),IFERROR(ABS(N5),0),IFERROR(ABS(Q5),0))>Threshold,"Yes","")
A6: 43 | B6: LL_Aqr_A | C6: 43 | D6: LL_Aqr_A | E6: By name | F6: =IF(SUMPRODUCT(--('Seq map'!$B$2:$B$13728=D6))=0,"Yes","No") -> No | G6: Miller26 | H6: Miller26 | I6: 1.1947 | J6: 1.1947 | K6: =IF(OR(I6="",J6=""),"",J6/I6-1) -> 0 | L6: 1.318 | M6: 1.318 | N6: =IF(OR(L6="",M6=""),"",M6/L6-1) -> 0 | O6: 6242 | P6: 6242 | Q6: =IF(OR(O6="",P6=""),"",P6/O6-1) -> 0 | R6: 0.04 | S6: 0.02 | T6: =IF(OR(R6="",S6=""),"",S6-R6) -> -0.02 | U6: =IF(MAX(IFERROR(ABS(K6),0),IFERROR(ABS(N6),0),IFERROR(ABS(Q6),0))>Threshold,"Yes","") | W6: type F9 → F3V
A7: 44 | B7: LL_Aqr_B | C7: 44 | D7: LL_Aqr_B | E7: By name | F7: =IF(SUMPRODUCT(--('Seq map'!$B$2:$B$13728=D7))=0,"Yes","No") -> No | G7: Miller26 | H7: Miller26 | I7: 1.0334 | J7: 1.0334 | K7: =IF(OR(I7="",J7=""),"",J7/I7-1) -> 0 | L7: 0.9927 | M7: 0.9927 | N7: =IF(OR(L7="",M7=""),"",M7/L7-1) -> 0 | O7: 5839 | P7: 5839 | Q7: =IF(OR(O7="",P7=""),"",P7/O7-1) -> 0 | R7: 0.05 | S7: 0.02 | T7: =IF(OR(R7="",S7=""),"",S7-R7) -> -0.03 | U7: =IF(MAX(IFERROR(ABS(K7),0),IFERROR(ABS(N7),0),IFERROR(ABS(Q7),0))>Threshold,"Yes","") | W7: type G3 → F8V
A8: 49 | B8: TYC_4535-148-1_A | C8: 49 | D8: BEPOP-3_A | E8: By parameters: different name | F8: =IF(SUMPRODUCT(--('Seq map'!$B$2:$B$13728=D8))=0,"Yes","No") -> Yes | G8: Maxted25 | H8: Maxted25b+Baycroft25 | I8: 1.084 | J8: 1.084 | K8: =IF(OR(I8="",J8=""),"",J8/I8-1) -> 0 | L8: 1.386 | M8: 1.386 | N8: =IF(OR(L8="",M8=""),"",M8/L8-1) -> 0 | O8: 6065 | P8: 6065 | Q8: =IF(OR(O8="",P8=""),"",P8/O8-1) -> 0 | R8: -0.02 | S8: -0.02 | T8: =IF(OR(R8="",S8=""),"",S8-R8) -> 0 | U8: =IF(MAX(IFERROR(ABS(K8),0),IFERROR(ABS(N8),0),IFERROR(ABS(Q8),0))>Threshold,"Yes","") | W8: type F9 → F9V
A9: 50 | B9: TYC_4535-148-1_B | C9: 50 | D9: BEPOP-3_B | E9: By parameters: different name | F9: =IF(SUMPRODUCT(--('Seq map'!$B$2:$B$13728=D9))=0,"Yes","No") -> Yes | G9: Maxted25 | H9: Maxted25b+Baycroft25 | I9: 0.262 | J9: 0.262 | K9: =IF(OR(I9="",J9=""),"",J9/I9-1) -> 0 | L9: 0.274 | M9: 0.274 | N9: =IF(OR(L9="",M9=""),"",M9/L9-1) -> 0 | O9: 3191 | P9: 3191 | Q9: =IF(OR(O9="",P9=""),"",P9/O9-1) -> 0 | R9: -0.02 | S9: -0.02 | T9: =IF(OR(R9="",S9=""),"",S9-R9) -> 0 | U9: =IF(MAX(IFERROR(ABS(K9),0),IFERROR(ABS(N9),0),IFERROR(ABS(Q9),0))>Threshold,"Yes","")
A10: 84 | B10: TIC17303250_A | C10: 85 | D10: TIC17303250_A | E10: By name | F10: =IF(SUMPRODUCT(--('Seq map'!$B$2:$B$13728=D10))=0,"Yes","No") -> No | G10: Pan25 | H10: Pan25 | I10: 0.714 | J10: 0.714 | K10: =IF(OR(I10="",J10=""),"",J10/I10-1) -> 0 | L10: 0.768 | M10: 0.768 | N10: =IF(OR(L10="",M10=""),"",M10/L10-1) -> 0 | O10: 5135 | P10: 5135 | Q10: =IF(OR(O10="",P10=""),"",P10/O10-1) -> 0 | R10: -0.04 | S10: -0.04 | T10: =IF(OR(R10="",S10=""),"",S10-R10) -> 0 | U10: =IF(MAX(IFERROR(ABS(K10),0),IFERROR(ABS(N10),0),IFERROR(ABS(Q10),0))>Threshold,"Yes","") | W10: type K1 → K1V
A11: 85 | B11: TIC17303250_B | C11: 86 | D11: TIC17303250_B | E11: By name | F11: =IF(SUMPRODUCT(--('Seq map'!$B$2:$B$13728=D11))=0,"Yes","No") -> No | G11: Pan25 | H11: Pan25 | I11: 0.696 | J11: 0.696 | K11: =IF(OR(I11="",J11=""),"",J11/I11-1) -> 0 | L11: 0.752 | M11: 0.752 | N11: =IF(OR(L11="",M11=""),"",M11/L11-1) -> 0 | O11: 5070 | P11: 5070 | Q11: =IF(OR(O11="",P11=""),"",P11/O11-1) -> 0 | R11: -0.06 | S11: -0.06 | T11: =IF(OR(R11="",S11=""),"",S11-R11) -> 0 | U11: =IF(MAX(IFERROR(ABS(K11),0),IFERROR(ABS(N11),0),IFERROR(ABS(Q11),0))>Threshold,"Yes","") | W11: type K2 → K2V
A12: 217 | B12: HD22064_A | C12: 223 | D12: HD22064_A | E12: By name | F12: =IF(SUMPRODUCT(--('Seq map'!$B$2:$B$13728=D12))=0,"Yes","No") -> No | G12: Maxted23 | H12: Maxted25b | I12: 1.345 | J12: 1.345 | K12: =IF(OR(I12="",J12=""),"",J12/I12-1) -> 0 | L12: 1.554 | M12: 1.554 | N12: =IF(OR(L12="",M12=""),"",M12/L12-1) -> 0 | O12: 6763 | P12: 6711 | Q12: =IF(OR(O12="",P12=""),"",P12/O12-1) -> -0.0076888955 | R12: -0.1812 | S12: -0.05 | T12: =IF(OR(R12="",S12=""),"",S12-R12) -> 0.1312 | U12: =IF(MAX(IFERROR(ABS(K12),0),IFERROR(ABS(N12),0),IFERROR(ABS(Q12),0))>Threshold,"Yes","")
A13: 218 | B13: HD22064_B | C13: 224 | D13: HD22064_B | E13: By name | F13: =IF(SUMPRODUCT(--('Seq map'!$B$2:$B$13728=D13))=0,"Yes","No") -> No | G13: Maxted23 | H13: Maxted25b | I13: 0.576 | J13: 0.576 | K13: =IF(OR(I13="",J13=""),"",J13/I13-1) -> 0 | L13: 0.595 | M13: 0.595 | N13: =IF(OR(L13="",M13=""),"",M13/L13-1) -> 0 | O13: 3700 | P13: 3486 | Q13: =IF(OR(O13="",P13=""),"",P13/O13-1) -> -0.057837838 | R13: -0.1812 | S13: -0.05 | T13: =IF(OR(R13="",S13=""),"",S13-R13) -> 0.1312 | U13: =IF(MAX(IFERROR(ABS(K13),0),IFERROR(ABS(N13),0),IFERROR(ABS(Q13),0))>Threshold,"Yes","") -> Yes
A14: 219 | B14: EBLM_J0113+31_A | C14: 225 | D14: EBLM_J0113+31_A | E14: By name | F14: =IF(SUMPRODUCT(--('Seq map'!$B$2:$B$13728=D14))=0,"Yes","No") -> No | G14: Maxted22 | H14: Maxted25b | I14: 1.029 | J14: 1.029 | K14: =IF(OR(I14="",J14=""),"",J14/I14-1) -> 0 | L14: 1.417 | M14: 1.417 | N14: =IF(OR(L14="",M14=""),"",M14/L14-1) -> 0 | O14: 6124 | P14: 6146 | Q14: =IF(OR(O14="",P14=""),"",P14/O14-1) -> 0.0035924233 | S14: -0.31 | T14: =IF(OR(R14="",S14=""),"",S14-R14) | U14: =IF(MAX(IFERROR(ABS(K14),0),IFERROR(ABS(N14),0),IFERROR(ABS(Q14),0))>Threshold,"Yes","") | V14: Meta
A15: 220 | B15: EBLM_J0113+31_B | C15: 226 | D15: EBLM_J0113+31_B | E15: By name | F15: =IF(SUMPRODUCT(--('Seq map'!$B$2:$B$13728=D15))=0,"Yes","No") -> No | G15: Maxted22 | H15: Maxted25b | I15: 0.197 | J15: 0.197 | K15: =IF(OR(I15="",J15=""),"",J15/I15-1) -> 0 | L15: 0.215 | M15: 0.215 | N15: =IF(OR(L15="",M15=""),"",M15/L15-1) -> 0 | O15: 3375 | P15: 3311 | Q15: =IF(OR(O15="",P15=""),"",P15/O15-1) -> -0.018962963 | S15: -0.31 | T15: =IF(OR(R15="",S15=""),"",S15-R15) | U15: =IF(MAX(IFERROR(ABS(K15),0),IFERROR(ABS(N15),0),IFERROR(ABS(Q15),0))>Threshold,"Yes","") | V15: Meta
A16: 280 | B16: KIC9540226_A | C16: 287 | D16: KIC9540226_B | E16: By parameters: A/B letters swapped | F16: =IF(SUMPRODUCT(--('Seq map'!$B$2:$B$13728=D16))=0,"Yes","No") -> No | G16: Brogaard18 | H16: Themessl18 | I16: 1.002 | J16: 1.015 | K16: =IF(OR(I16="",J16=""),"",J16/I16-1) -> 0.012974052 | L16: 1.014 | M16: 1.034 | N16: =IF(OR(L16="",M16=""),"",M16/L16-1) -> 0.019723866 | O16: 6157 | P16: 6157 | Q16: =IF(OR(O16="",P16=""),"",P16/O16-1) -> 0 | R16: -0.23 | S16: -0.31 | T16: =IF(OR(R16="",S16=""),"",S16-R16) -> -0.08 | U16: =IF(MAX(IFERROR(ABS(K16),0),IFERROR(ABS(N16),0),IFERROR(ABS(Q16),0))>Threshold,"Yes","")
A17: 281 | B17: KIC9540226_B | C17: 286 | D17: KIC9540226_A | E17: By parameters: A/B letters swapped | F17: =IF(SUMPRODUCT(--('Seq map'!$B$2:$B$13728=D17))=0,"Yes","No") -> No | G17: Brogaard18 | H17: Themessl18 | I17: 1.378 | J17: 1.39 | K17: =IF(OR(I17="",J17=""),"",J17/I17-1) -> 0.0087082729 | L17: 13.06 | M17: 13.43 | N17: =IF(OR(L17="",M17=""),"",M17/L17-1) -> 0.028330781 | O17: 4680 | P17: 4585 | Q17: =IF(OR(O17="",P17=""),"",P17/O17-1) -> -0.020299145 | R17: -0.23 | S17: -0.31 | T17: =IF(OR(R17="",S17=""),"",S17-R17) -> -0.08 | U17: =IF(MAX(IFERROR(ABS(K17),0),IFERROR(ABS(N17),0),IFERROR(ABS(Q17),0))>Threshold,"Yes","")
A18: 320 | B18: KIC8410637_B | C18: 326 | D18: KIC8410637_B | E18: By name | F18: =IF(SUMPRODUCT(--('Seq map'!$B$2:$B$13728=D18))=0,"Yes","No") -> No | G18: Themessl18 | H18: Themessl18 | I18: 1.472 | J18: 1.472 | K18: =IF(OR(I18="",J18=""),"",J18/I18-1) -> 0 | L18: 10.596 | M18: 10.596 | N18: =IF(OR(L18="",M18=""),"",M18/L18-1) -> 0 | O18: 4605 | P18: 4605 | Q18: =IF(OR(O18="",P18=""),"",P18/O18-1) -> 0 | R18: 0.0508 | S18: 0.02 | T18: =IF(OR(R18="",S18=""),"",S18-R18) -> -0.0308 | U18: =IF(MAX(IFERROR(ABS(K18),0),IFERROR(ABS(N18),0),IFERROR(ABS(Q18),0))>Threshold,"Yes","") | V18: oblateness
A19: 321 | B19: KIC5640750_B | C19: 327 | D19: KIC5640750_B | E19: By name | F19: =IF(SUMPRODUCT(--('Seq map'!$B$2:$B$13728=D19))=0,"Yes","No") -> No | G19: Themessl18 | H19: Themessl18 | I19: 1.158 | J19: 1.515 | K19: =IF(OR(I19="",J19=""),"",J19/I19-1) -> 0.30829016 | L19: 13.12 | M19: 14.06 | N19: =IF(OR(L19="",M19=""),"",M19/L19-1) -> 0.071646341 | O19: 4525 | P19: 4525 | Q19: =IF(OR(O19="",P19=""),"",P19/O19-1) -> 0 | R19: 0.24 | S19: -0.29 | T19: =IF(OR(R19="",S19=""),"",S19-R19) -> -0.53 | U19: =IF(MAX(IFERROR(ABS(K19),0),IFERROR(ABS(N19),0),IFERROR(ABS(Q19),0))>Threshold,"Yes","") -> Yes | V19: oblateness
A20: 5691 | B20: KIC10001167_A | C20: 5697 | D20: KIC10001167 | E20: By parameters: original row had no A/B label | F20: =IF(SUMPRODUCT(--('Seq map'!$B$2:$B$13728=D20))=0,"Yes","No") -> Yes | G20: Pinsonneault25 | H20: Thomsen25 | I20: 1.0105 | J20: 0.9337 | K20: =IF(OR(I20="",J20=""),"",J20/I20-1) -> -0.076001979 | L20: 13.1666 | M20: 13.03 | N20: =IF(OR(L20="",M20=""),"",M20/L20-1) -> -0.010374736 | O20: 4597.63 | P20: 4625 | Q20: =IF(OR(O20="",P20=""),"",P20/O20-1) -> 0.0059530671 | R20: -0.6768 | S20: -0.73 | T20: =IF(OR(R20="",S20=""),"",S20-R20) -> -0.0532 | U20: =IF(MAX(IFERROR(ABS(K20),0),IFERROR(ABS(N20),0),IFERROR(ABS(Q20),0))>Threshold,"Yes","") -> Yes | V20: orbit_a, detached, oblateness | W20: mode A → EB
A21: 7491 | B21: KIC11235323_A | C21: 7519 | D21: KIC11235323_A | E21: By name | F21: =IF(SUMPRODUCT(--('Seq map'!$B$2:$B$13728=D21))=0,"Yes","No") -> No | G21: Benbakoura21 | H21: Benbakoura21 | I21: 1.03 | J21: 1.03 | K21: =IF(OR(I21="",J21=""),"",J21/I21-1) -> 0 | L21: 3.578 | M21: 3.578 | N21: =IF(OR(L21="",M21=""),"",M21/L21-1) -> 0 | O21: 4840 | P21: 4840 | Q21: =IF(OR(O21="",P21=""),"",P21/O21-1) -> 0 | R21: -0.4 | S21: -0.36 | T21: =IF(OR(R21="",S21=""),"",S21-R21) -> 0.04 | U21: =IF(MAX(IFERROR(ABS(K21),0),IFERROR(ABS(N21),0),IFERROR(ABS(Q21),0))>Threshold,"Yes","")
A22: 7492 | B22: KIC11235323_B | C22: 7520 | D22: KIC11235323_B | E22: By name | F22: =IF(SUMPRODUCT(--('Seq map'!$B$2:$B$13728=D22))=0,"Yes","No") -> No | G22: Benbakoura21 | H22: Benbakoura21 | I22: 0.989 | J22: 0.989 | K22: =IF(OR(I22="",J22=""),"",J22/I22-1) -> 0 | L22: 1.544 | M22: 1.544 | N22: =IF(OR(L22="",M22=""),"",M22/L22-1) -> 0 | O22: 6319 | P22: 6319 | Q22: =IF(OR(O22="",P22=""),"",P22/O22-1) -> 0 | R22: -0.4 | S22: -0.36 | T22: =IF(OR(R22="",S22=""),"",S22-R22) -> 0.04 | U22: =IF(MAX(IFERROR(ABS(K22),0),IFERROR(ABS(N22),0),IFERROR(ABS(Q22),0))>Threshold,"Yes","")
A23: 12595 | B23: V785_Cep_A | C23: 12625 | D23: Cl*_NGC_188_KS_V12_A | E23: By parameters: different name | F23: =IF(SUMPRODUCT(--('Seq map'!$B$2:$B$13728=D23))=0,"Yes","No") -> Yes | G23: Eker14+18 | H23: Yakut25 | I23: 1.102 | J23: 1.099 | K23: =IF(OR(I23="",J23=""),"",J23/I23-1) -> -0.002722323 | L23: 1.425 | M23: 1.444 | N23: =IF(OR(L23="",M23=""),"",M23/L23-1) -> 0.013333333 | O23: 5900 | P23: 5857 | Q23: =IF(OR(O23="",P23=""),"",P23/O23-1) -> -0.0072881356 | S23: 0.025 | T23: =IF(OR(R23="",S23=""),"",S23-R23) | U23: =IF(MAX(IFERROR(ABS(K23),0),IFERROR(ABS(N23),0),IFERROR(ABS(Q23),0))>Threshold,"Yes","") | V23: Meta, orbit_a, detached, oblateness
A24: 12596 | B24: V785_Cep_B | C24: 12626 | D24: Cl*_NGC_188_KS_V12_B | E24: By parameters: different name | F24: =IF(SUMPRODUCT(--('Seq map'!$B$2:$B$13728=D24))=0,"Yes","No") -> Yes | G24: Eker14+18 | H24: Yakut25 | I24: 1.08 | J24: 1.075 | K24: =IF(OR(I24="",J24=""),"",J24/I24-1) -> -0.0046296296 | L24: 1.374 | M24: 1.412 | N24: =IF(OR(L24="",M24=""),"",M24/L24-1) -> 0.027656477 | O24: 5875 | P24: 6019 | Q24: =IF(OR(O24="",P24=""),"",P24/O24-1) -> 0.024510638 | S24: 0.025 | T24: =IF(OR(R24="",S24=""),"",S24-R24) | U24: =IF(MAX(IFERROR(ABS(K24),0),IFERROR(ABS(N24),0),IFERROR(ABS(Q24),0))>Threshold,"Yes","") | V24: Meta, orbit_a, detached, oblateness
A25: 13022 | B25: AI_Phe_A | C25: 13055 | D25: AI_Phe_B | E25: By parameters: A/B letters swapped | F25: =IF(SUMPRODUCT(--('Seq map'!$B$2:$B$13728=D25))=0,"Yes","No") -> No | G25: malkov07 | H25: Maxted25b+26 | I25: 1.19 | J25: 1.194 | K25: =IF(OR(I25="",J25=""),"",J25/I25-1) -> 0.0033613445 | L25: 1.762 | M25: 1.805 | N25: =IF(OR(L25="",M25=""),"",M25/L25-1) -> 0.024404086 | O25: 6310 | P25: 6259 | Q25: =IF(OR(O25="",P25=""),"",P25/O25-1) -> -0.0080824089 | R25: -0.14 | S25: -0.16 | T25: =IF(OR(R25="",S25=""),"",S25-R25) -> -0.02 | U25: =IF(MAX(IFERROR(ABS(K25),0),IFERROR(ABS(N25),0),IFERROR(ABS(Q25),0))>Threshold,"Yes","") | V25: logg, orbit_a, oblateness | W25: type F → F7V
A26: 13023 | B26: AI_Phe_B | C26: 13054 | D26: AI_Phe_A | E26: By parameters: A/B letters swapped | F26: =IF(SUMPRODUCT(--('Seq map'!$B$2:$B$13728=D26))=0,"Yes","No") -> No | G26: torres10 | H26: Maxted25b+26 | I26: 1.234 | J26: 1.244 | K26: =IF(OR(I26="",J26=""),"",J26/I26-1) -> 0.0081037277 | L26: 2.932 | M26: 2.933 | N26: =IF(OR(L26="",M26=""),"",M26/L26-1) -> 0.00034106412 | O26: 5010 | P26: 5112 | Q26: =IF(OR(O26="",P26=""),"",P26/O26-1) -> 0.020359281 | R26: -0.14 | S26: -0.08 | T26: =IF(OR(R26="",S26=""),"",S26-R26) -> 0.06 | U26: =IF(MAX(IFERROR(ABS(K26),0),IFERROR(ABS(N26),0),IFERROR(ABS(Q26),0))>Threshold,"Yes","") | V26: orbit_a, oblateness | W26: class PMS → SG; type K → K0IV
A27: 13034 | B27: BK_Peg_A | C27: 13066 | D27: BK_Peg_A | E27: By name | F27: =IF(SUMPRODUCT(--('Seq map'!$B$2:$B$13728=D27))=0,"Yes","No") -> No | G27: malkov07 | H27: Kutluay26 | I27: 1.43 | J27: 1.4109 | K27: =IF(OR(I27="",J27=""),"",J27/I27-1) -> -0.013356643 | L27: 1.97 | M27: 1.9901 | N27: =IF(OR(L27="",M27=""),"",M27/L27-1) -> 0.010203046 | O27: 6053 | P27: 6265 | Q27: =IF(OR(O27="",P27=""),"",P27/O27-1) -> 0.035023955 | R27: -0.12 | S27: -0.12 | T27: =IF(OR(R27="",S27=""),"",S27-R27) -> 0 | U27: =IF(MAX(IFERROR(ABS(K27),0),IFERROR(ABS(N27),0),IFERROR(ABS(Q27),0))>Threshold,"Yes","") -> Yes | V27: logg, orbit_a, oblateness | W27: type F → F8V
A28: 13035 | B28: BK_Peg_B | C28: 13067 | D28: BK_Peg_B | E28: By name | F28: =IF(SUMPRODUCT(--('Seq map'!$B$2:$B$13728=D28))=0,"Yes","No") -> No | G28: malkov07 | H28: Kutluay26 | I28: 1.28 | J28: 1.2545 | K28: =IF(OR(I28="",J28=""),"",J28/I28-1) -> -0.019921875 | L28: 1.57 | M28: 1.4599 | N28: =IF(OR(L28="",M28=""),"",M28/L28-1) -> -0.070127389 | O28: 6123 | P28: 6320 | Q28: =IF(OR(O28="",P28=""),"",P28/O28-1) -> 0.032173771 | R28: -0.12 | S28: -0.12 | T28: =IF(OR(R28="",S28=""),"",S28-R28) -> 0 | U28: =IF(MAX(IFERROR(ABS(K28),0),IFERROR(ABS(N28),0),IFERROR(ABS(Q28),0))>Threshold,"Yes","") -> Yes | V28: logg, orbit_a, oblateness | W28: type F → F7V
A29: 13066 | B29: KIC6131659_A | C29: 13098 | D29: KIC_6131659_A | E29: By name (format differs) | F29: =IF(SUMPRODUCT(--('Seq map'!$B$2:$B$13728=D29))=0,"Yes","No") -> Yes | G29: eker14 | H29: Maxted25a | I29: 0.922 | J29: 0.9355 | K29: =IF(OR(I29="",J29=""),"",J29/I29-1) -> 0.014642082 | L29: 0.88 | M29: 0.8844 | N29: =IF(OR(L29="",M29=""),"",M29/L29-1) -> 0.005 | O29: 5660 | P29: 5660 | Q29: =IF(OR(O29="",P29=""),"",P29/O29-1) -> 0 | R29: -0.21 | S29: -0.23 | T29: =IF(OR(R29="",S29=""),"",S29-R29) -> -0.02 | U29: =IF(MAX(IFERROR(ABS(K29),0),IFERROR(ABS(N29),0),IFERROR(ABS(Q29),0))>Threshold,"Yes","") | V29: orbit_a, oblateness
A30: 13067 | B30: KIC6131659_B | C30: 13099 | D30: KIC_6131659_B | E30: By name (format differs) | F30: =IF(SUMPRODUCT(--('Seq map'!$B$2:$B$13728=D30))=0,"Yes","No") -> Yes | G30: eker14 | H30: Maxted25a | I30: 0.685 | J30: 0.6997 | K30: =IF(OR(I30="",J30=""),"",J30/I30-1) -> 0.021459854 | L30: 0.64 | M30: 0.6518 | N30: =IF(OR(L30="",M30=""),"",M30/L30-1) -> 0.0184375 | O30: 4780 | P30: 4780 | Q30: =IF(OR(O30="",P30=""),"",P30/O30-1) -> 0 | R30: -0.21 | S30: -0.23 | T30: =IF(OR(R30="",S30=""),"",S30-R30) -> -0.02 | U30: =IF(MAX(IFERROR(ABS(K30),0),IFERROR(ABS(N30),0),IFERROR(ABS(Q30),0))>Threshold,"Yes","") | V30: orbit_a, oblateness
A31: 13068 | B31: LV_Her_A | C31: 13100 | D31: LV_Her_A | E31: By name | F31: =IF(SUMPRODUCT(--('Seq map'!$B$2:$B$13728=D31))=0,"Yes","No") -> No | G31: eker14 | H31: Torres09 | I31: 1.192 | J31: 1.193 | K31: =IF(OR(I31="",J31=""),"",J31/I31-1) -> 0.00083892617 | L31: 1.358 | M31: 1.358 | N31: =IF(OR(L31="",M31=""),"",M31/L31-1) -> 0 | O31: 6060 | P31: 6060 | Q31: =IF(OR(O31="",P31=""),"",P31/O31-1) -> 0 | R31: 0.08 | S31: 0.08 | T31: =IF(OR(R31="",S31=""),"",S31-R31) -> 0 | U31: =IF(MAX(IFERROR(ABS(K31),0),IFERROR(ABS(N31),0),IFERROR(ABS(Q31),0))>Threshold,"Yes","") | V31: orbit_a, oblateness | W31: type F → F9V
A32: 13069 | B32: LV_Her_B | C32: 13101 | D32: LV_Her_B | E32: By name | F32: =IF(SUMPRODUCT(--('Seq map'!$B$2:$B$13728=D32))=0,"Yes","No") -> No | G32: eker14 | H32: Torres09 | I32: 1.169 | J32: 1.1698 | K32: =IF(OR(I32="",J32=""),"",J32/I32-1) -> 0.00068434559 | L32: 1.313 | M32: 1.313 | N32: =IF(OR(L32="",M32=""),"",M32/L32-1) -> 0 | O32: 6030 | P32: 6030 | Q32: =IF(OR(O32="",P32=""),"",P32/O32-1) -> 0 | R32: 0.08 | S32: 0.08 | T32: =IF(OR(R32="",S32=""),"",S32-R32) -> 0 | U32: =IF(MAX(IFERROR(ABS(K32),0),IFERROR(ABS(N32),0),IFERROR(ABS(Q32),0))>Threshold,"Yes","") | V32: orbit_a, oblateness | W32: type F → F9V

Sheet Added rows
A1: Seq in merged file | B1: Final ID | C1: System | D1: Kind | E1: Catalog | F1: M (Msun) | G1: R (Rsun) | H1: Teff (K) | I1: Meta (dex) | J1: Note
A2: 13697 | B2: TYC_7073-2399-1_A | C2: TYC_7073-2399-1 | D2: New system | E2: Hahlin26 | F2: 1.1651 | G2: 1.0872 | H2: 6064 | I2: 0.115
A3: 13698 | B3: TYC_7073-2399-1_B | C3: TYC_7073-2399-1 | D3: New system | E3: Hahlin26 | F3: 0.48001 | G3: 0.4549 | H3: 3527 | I3: 0.115
A4: 13699 | B4: HD287990_A | C4: HD287990 | D4: New system | E4: Hahlin26 | F4: 1.3431 | G4: 1.654 | H4: 6486 | I4: 0.096
A5: 13700 | B5: HD287990_B | C5: HD287990 | D5: New system | E5: Hahlin26 | F5: 0.6732 | G5: 0.6269 | H5: 4384 | I5: 0.096
A6: 13701 | B6: TYC_5333-1460-1_A | C6: TYC_5333-1460-1 | D6: New system | E6: Hahlin26 | F6: 0.9644 | G6: 1.2055 | H6: 6038 | I6: -0.316
A7: 13702 | B7: TYC_5333-1460-1_B | C7: TYC_5333-1460-1 | D7: New system | E7: Hahlin26 | F7: 0.5195 | G7: 0.50307 | H7: 3837 | I7: -0.316
A8: 13703 | B8: CD-27_2812_A | C8: CD-27_2812 | D8: New system | E8: Adshead26 | F8: 1.3597 | G8: 1.7207 | H8: 6197 | I8: 0.15
A9: 13704 | B9: CD-27_2812_B | C9: CD-27_2812 | D9: New system | E9: Adshead26 | F9: 0.5624 | G9: 0.5307 | H9: 3770 | I9: 0.15
A10: 13707 | B10: TOI-1338_A | C10: TOI-1338 | D10: New system | E10: Maxted25b | H10: 6054 | I10: 0.01 | J10: Only Teff and Meta
A11: 13708 | B11: TOI-1338_B | C11: TOI-1338 | D11: New system | E11: Maxted25b | H11: 3327 | I11: 0.01 | J11: Only Teff and Meta
A12: 13709 | B12: KIC7118545_A | C12: KIC7118545 | D12: New system | E12: Ozdarcan26 | F12: 1.26 | G12: 1.28 | H12: 6503 | I12: -0.11
A13: 13710 | B13: KIC7118545_B | C13: KIC7118545 | D13: New system | E13: Ozdarcan26 | F13: 0.666 | G13: 0.607 | H13: 4047 | I13: -0.11
A14: 13711 | B14: KIC10215422_A | C14: KIC10215422 | D14: New system | E14: Ozdarcan26 | F14: 1.04 | G14: 1.168 | H14: 5676 | I14: 0.234
A15: 13712 | B15: KIC10215422_B | C15: KIC10215422 | D15: New system | E15: Ozdarcan26 | F15: 0.691 | G15: 0.659 | H15: 4122 | I15: 0.234
A16: 13713 | B16: KIC9164836_A | C16: KIC9164836 | D16: New system | E16: Ozdarcan26 | F16: 1.02 | G16: 1.094 | H16: 5952 | I16: -0.08
A17: 13714 | B17: KIC9164836_B | C17: KIC9164836 | D17: New system | E17: Ozdarcan26 | F17: 0.685 | G17: 0.628 | H17: 4260 | I17: -0.08
A18: 13715 | B18: KIC9353182_A | C18: KIC9353182 | D18: New system | E18: Ozdarcan26 | F18: 1.3 | G18: 1.833 | H18: 5997 | I18: 0.192
A19: 13716 | B19: KIC9353182_B | C19: KIC9353182 | D19: New system | E19: Ozdarcan26 | F19: 0.622 | G19: 0.595 | H19: 3968 | I19: 0.192
A20: 13717 | B20: KIC11619964_A | C20: KIC11619964 | D20: New system | E20: Ozdarcan26 | F20: 0.975 | G20: 0.955 | H20: 5823 | I20: -0.03
A21: 13718 | B21: KIC11619964_B | C21: KIC11619964 | D21: New system | E21: Ozdarcan26 | F21: 0.624 | G21: 0.559 | H21: 4045 | I21: -0.03
A22: 13719 | B22: KIC4075064_A | C22: KIC4075064 | D22: New system | E22: Ozdarcan26 | F22: 0.814 | G22: 0.713 | H22: 5318 | I22: -0.19
A23: 13720 | B23: KIC4075064_B | C23: KIC4075064 | D23: New system | E23: Ozdarcan26 | F23: 0.754 | G23: 0.674 | H23: 4747 | I23: -0.19
... A26: 13723 | B26: Kepler-16_A | C26: Kepler-16 | D26: New system | E26: Doyle11 | F26: 0.6897 | G26: 0.6489 | H26: 4450 | I26: -0.3
A27: 13724 | B27: Kepler-16_B | C27: Kepler-16 | D27: New system | E27: Doyle11 | F27: 0.20255 | G27: 0.22623 | I27: -0.3
A28: 13725 | B28: KIC10001167_B | C28: KIC10001167 | D28: Companion of a system already in the file | E28: Thomsen25 | F28: 0.8388 | G28: 0.995 | H28: 6031 | I28: -0.73
A29: 13726 | B29: KIC5640750_A | C29: KIC5640750 | D29: Companion of a system already in the file | E29: Themessl18 | F29: 1.292 | G29: 1.853 | H29: 5844 | I29: 0.08
A30: 13727 | B30: KIC8410637_A | C30: KIC8410637 | D30: Companion of a system already in the file | E30: Themessl18 | F30: 1.309 | G30: 1.556 | H30: 6066 | I30: 0.01

Sheet Deleted rows
A1: Seq in merged file | B1: Deleted ID | C1: Deleted row from | D1: Catalog (deleted) | E1: Same star kept as | F1: Kept row from | G1: Catalog (kept) | H1: M deleted (Msun) | I1: M kept (Msun) | J1: ΔM (kept vs deleted) | K1: R deleted (Rsun) | L1: R kept (Rsun) | M1: ΔR (kept vs deleted) | N1: Teff deleted (K) | O1: Teff kept (K) | P1: ΔTeff (kept vs deleted) | Q1: orbit_a deleted (Rsun) | R1: orbit_a kept (Rsun) | S1: Your note | T1: Why the merge kept both
A2: 29 | B2: TIC37606218__A | C2: Original file | D2: CakirliDec25 | E2: CD-27_2812_A | F2: Update file | G2: Adshead26 | H2: 1.35 | I2: 1.3597 | J2: =IF(OR(H2="",I2=""),"",I2/H2-1) -> 0.0071851852 | K2: 1.611 | L2: 1.7207 | M2: =IF(OR(K2="",L2=""),"",L2/K2-1) -> 0.068094351 | N2: 6502 | O2: 6197 | P2: =IF(OR(N2="",O2=""),"",O2/N2-1) -> -0.046908643 | Q2: 20.6 | R2: 20.6419 | S2: R 1.61 vs 1.72 | T2: Pair outside the merge's 3 % tolerance
A3: 30 | B3: TIC37606218__B | C3: Original file | D3: CakirliDec25 | E3: CD-27_2812_B | F3: Update file | G3: Adshead26 | H3: 0.563 | I3: 0.5624 | J3: =IF(OR(H3="",I3=""),"",I3/H3-1) -> -0.0010657194 | K3: 0.552 | L3: 0.5307 | M3: =IF(OR(K3="",L3=""),"",L3/K3-1) -> -0.038586957 | N3: 3923 | O3: 3770 | P3: =IF(OR(N3="",O3=""),"",O3/N3-1) -> -0.039000765 | Q3: 20.6 | R3: 20.6419 | S3: R 1.61 vs 1.72 | T3: Pair outside the merge's 3 % tolerance
A4: 35 | B4: TIC138857475_A | C4: Original file | D4: CakirliDec25 | E4: HD287990_A | F4: Update file | G4: Hahlin26 | H4: 1.481 | I4: 1.3431 | J4: =IF(OR(H4="",I4=""),"",I4/H4-1) -> -0.093112762 | K4: 1.704 | L4: 1.654 | M4: =IF(OR(K4="",L4=""),"",L4/K4-1) -> -0.029342723 | N4: 6533 | O4: 6486 | P4: =IF(OR(N4="",O4=""),"",O4/N4-1) -> -0.0071942446 | Q4: 30.2 | R4: 29.3 | S4: M 1.48 vs 1.34 | T4: Pair outside the merge's 3 % tolerance
A5: 36 | B5: TIC138857475_B | C5: Original file | D5: CakirliDec25 | E5: HD287990_B | F5: Update file | G5: Hahlin26 | H5: 0.726 | I5: 0.6732 | J5: =IF(OR(H5="",I5=""),"",I5/H5-1) -> -0.072727273 | K5: 0.643 | L5: 0.6269 | M5: =IF(OR(K5="",L5=""),"",L5/K5-1) -> -0.02503888 | N5: 4325 | O5: 4384 | P5: =IF(OR(N5="",O5=""),"",O5/N5-1) -> 0.013641618 | Q5: 30.2 | R5: 29.3 | S5: M 1.48 vs 1.34 | T5: Pair outside the merge's 3 % tolerance
A6: 39 | B6: TIC287841093_A | C6: Original file | D6: CakirliDec25 | E6: TYC_5333-1460-1_A | F6: Update file | G6: Hahlin26 | H6: 0.991 | I6: 0.9644 | J6: =IF(OR(H6="",I6=""),"",I6/H6-1) -> -0.026841574 | K6: 1.209 | L6: 1.2055 | M6: =IF(OR(K6="",L6=""),"",L6/K6-1) -> -0.0028949545 | N6: 5931 | O6: 6038 | P6: =IF(OR(N6="",O6=""),"",O6/N6-1) -> 0.018040803 | Q6: 33 | R6: 32.604 | T6: Pair outside the merge's 3 % tolerance
A7: 40 | B7: TIC287841093_B | C7: Original file | D7: CakirliDec25 | E7: TYC_5333-1460-1_B | F7: Update file | G7: Hahlin26 | H7: 0.546 | I7: 0.5195 | J7: =IF(OR(H7="",I7=""),"",I7/H7-1) -> -0.048534799 | K7: 0.504 | L7: 0.50307 | M7: =IF(OR(K7="",L7=""),"",L7/K7-1) -> -0.0018452381 | N7: 3852 | O7: 3837 | P7: =IF(OR(N7="",O7=""),"",O7/N7-1) -> -0.003894081 | Q7: 33 | R7: 32.604 | T7: Pair outside the merge's 3 % tolerance
A8: 13705 | B8: CPD-54_810_A | C8: Update file | D8: Maxted25b | E8: ASAS_J051753-5406,0_A | F8: Original file | G8: Miller22 | I8: 1.3094 | J8: =IF(OR(H8="",I8=""),"",I8/H8-1) | L8: 1.9288 | M8: =IF(OR(K8="",L8=""),"",L8/K8-1) | N8: 6462 | O8: 6462 | P8: =IF(OR(N8="",O8=""),"",O8/N8-1) -> 0 | R8: 49.718 | S8: Teff only, same star | T8: Teff only: not searched by parameters
A9: 13706 | B9: CPD-54_810_B | C9: Update file | D9: Maxted25b | E9: ASAS_J051753-5406,0_B | F9: Original file | G9: Miller22 | I9: 1.0896 | J9: =IF(OR(H9="",I9=""),"",I9/H9-1) | L9: 1.1815 | M9: =IF(OR(K9="",L9=""),"",L9/K9-1) | N9: 6333 | O9: 6331 | P9: =IF(OR(N9="",O9=""),"",O9/N9-1) -> -0.0003158061 | R9: 49.718 | S9: Teff only, same star | T9: Teff only: not searched by parameters

Sheet Cell changes
A1: Seq in merged file | B1: Final ID | C1: Original ID | D1: Column | E1: Original value | F1: Final value | G1: Kind
A2: 27 | B2: HD4875_A | C2: TIC28051929_A | D2: M | E2: 1.088 | F2: 1.115 | G2: changed
A3: 27 | B3: HD4875_A | C3: TIC28051929_A | D3: eM1 | E3: 0.007 | F3: 0.0066 | G3: changed
A4: 27 | B4: HD4875_A | C4: TIC28051929_A | D4: eM2 | E4: 0.007 | F4: 0.0066 | G4: changed
A5: 27 | B5: HD4875_A | C5: TIC28051929_A | D5: R | E5: 1.285 | F5: 1.295 | G5: changed
A6: 27 | B6: HD4875_A | C6: TIC28051929_A | D6: eR1 | E6: 0.003 | F6: 0.0059 | G6: changed
A7: 27 | B7: HD4875_A | C7: TIC28051929_A | D7: eR2 | E7: 0.003 | F7: 0.0059 | G7: changed
A8: 27 | B8: HD4875_A | C8: TIC28051929_A | D8: Teff | E8: 5985 | F8: 6013 | G8: changed
A9: 27 | B9: HD4875_A | C9: TIC28051929_A | D9: eTeff1 | E9: 140 | F9: 25 | G9: changed
A10: 27 | B10: HD4875_A | C10: TIC28051929_A | D10: eTeff2 | E10: 140 | F10: 25 | G10: changed
A11: 27 | B11: HD4875_A | C11: TIC28051929_A | D11: L | E11: 1.91 | F11: 1.954 | G11: changed
A12: 27 | B12: HD4875_A | C12: TIC28051929_A | D12: eL1 | E12: 0.06 | F12: 0.027 | G12: changed
A13: 27 | B13: HD4875_A | C13: TIC28051929_A | D13: eL2 | E13: 0.06 | F13: 0.027 | G13: changed
A14: 27 | B14: HD4875_A | C14: TIC28051929_A | D14: Meta | E14: NA | F14: 0.119 | G14: filled
A15: 27 | B15: HD4875_A | C15: TIC28051929_A | D15: eMeta1 | E15: NA | F15: 0.007 | G15: filled
A16: 27 | B16: HD4875_A | C16: TIC28051929_A | D16: eMeta2 | E16: NA | F16: 0.007 | G16: filled
A17: 27 | B17: HD4875_A | C17: TIC28051929_A | D17: logg | E17: 4.256 | F17: 4.26 | G17: changed
A18: 27 | B18: HD4875_A | C18: TIC28051929_A | D18: elogg1 | E18: 0.001 | F18: 0.0038 | G18: changed
A19: 27 | B19: HD4875_A | C19: TIC28051929_A | D19: elogg2 | E19: 0.001 | F19: 0.0038 | G19: changed
A20: 27 | B20: HD4875_A | C20: TIC28051929_A | D20: rho | E20: 0.5128 | F20: 0.5135 | G20: changed
A21: 27 | B21: HD4875_A | C21: TIC28051929_A | D21: erho1 | E21: 0.0049 | F21: 0.0065 | G21: changed
A22: 27 | B22: HD4875_A | C22: TIC28051929_A | D22: erho2 | E22: 0.0049 | F22: 0.0065 | G22: changed
A23: 27 | B23: HD4875_A | C23: TIC28051929_A | D23: type | E23: F/G | F23: G3V | G23: changed
A24: 27 | B24: HD4875_A | C24: TIC28051929_A | D24: catalog | E24: CakirliDec25 | F24: Hahlin26 | G24: changed
A25: 27 | B25: HD4875_A | C25: TIC28051929_A | D25: orbit_a | E25: 27.6 | F25: 27.83 | G25: changed
A26: 27 | B26: HD4875_A | C26: TIC28051929_A | D26: eOrbit_a | E26: 0.054 | F26: 0.04 | G26: changed
A27: 27 | B27: HD4875_A | C27: TIC28051929_A | D27: oblateness | E27: 0.0001684 | F27: 0.0001676 | G27: changed
A28: 27 | B28: HD4875_A | C28: TIC28051929_A | D28: eoblateness1 | E28: 1.7e-06 | F28: 2.5e-06 | G28: changed
A29: 27 | B29: HD4875_A | C29: TIC28051929_A | D29: eoblateness2 | E29: 1.7e-06 | F29: 2.5e-06 | G29: changed
A30: 28 | B30: HD4875_B | C30: TIC28051929_B | D30: M | E30: 0.432 | F30: 0.4405 | G30: changed
A31: 28 | B31: HD4875_B | C31: TIC28051929_B | D31: eM1 | E31: 0.002 | F31: 0.0015 | G31: changed
A32: 28 | B32: HD4875_B | C32: TIC28051929_B | D32: eM2 | E32: 0.002 | F32: 0.0015 | G32: changed
A33: 28 | B33: HD4875_B | C33: TIC28051929_B | D33: R | E33: 0.4133 | F33: 0.4209 | G33: changed
A34: 28 | B34: HD4875_B | C34: TIC28051929_B | D34: eR1 | E34: 0.0009 | F34: 0.0021 | G34: changed
A35: 28 | B35: HD4875_B | C35: TIC28051929_B | D35: eR2 | E35: 0.0009 | F35: 0.0021 | G35: changed
A36: 28 | B36: HD4875_B | C36: TIC28051929_B | D36: Teff | E36: 3581 | F36: 3425 | G36: changed
... A41: 28 | B41: HD4875_B | C41: TIC28051929_B | D41: eL2 | E41: 0 | F41: 0.00088 | G41: changed
A42: 28 | B42: HD4875_B | C42: TIC28051929_B | D42: Meta | E42: NA | F42: 0.119 | G42: filled
A43: 28 | B43: HD4875_B | C43: TIC28051929_B | D43: eMeta1 | E43: NA | F43: 0.007 | G43: filled
A44: 28 | B44: HD4875_B | C44: TIC28051929_B | D44: eMeta2 | E44: NA | F44: 0.007 | G44: filled
...

Sheet Seq map
A1: Seq in merged file | B1: ID in merged file | C1: Status | D1: Original Seq (same star) | E1: Original ID (same star) | F1: Original Seq (same ID) | G1: Seq changed (same ID) | H1: Seq if renumbered 1..N after deletions | I1: Deleted rows up to here
A2: 1 | B2: G_158-50_A | C2: Untouched | D2: 1 | E2: G_158-50_A | F2: 1 | G2: =IF(OR(F2="",C2="Deleted"),"",IF(F2<>A2,"Yes","No")) -> No | H2: =IF(C2="Deleted","",A2-I2) -> 1 | I2: =N(I1)+IF(C2="Deleted",1,0) -> 0
A3: 2 | B3: G_158-50_B | C3: Untouched | D3: 2 | E3: G_158-50_B | F3: 2 | G3: =IF(OR(F3="",C3="Deleted"),"",IF(F3<>A3,"Yes","No")) -> No | H3: =IF(C3="Deleted","",A3-I3) -> 2 | I3: =N(I2)+IF(C3="Deleted",1,0) -> 0
A4: 3 | B4: GJ_54_A | C4: Untouched | D4: 3 | E4: GJ_54_A | F4: 3 | G4: =IF(OR(F4="",C4="Deleted"),"",IF(F4<>A4,"Yes","No")) -> No | H4: =IF(C4="Deleted","",A4-I4) -> 3 | I4: =N(I3)+IF(C4="Deleted",1,0) -> 0
A5: 4 | B5: GJ_54_B | C5: Untouched | D5: 4 | E5: GJ_54_B | F5: 4 | G5: =IF(OR(F5="",C5="Deleted"),"",IF(F5<>A5,"Yes","No")) -> No | H5: =IF(C5="Deleted","",A5-I5) -> 4 | I5: =N(I4)+IF(C5="Deleted",1,0) -> 0
A6: 5 | B6: GJ_65_A | C6: Untouched | D6: 5 | E6: GJ_65_A | F6: 5 | G6: =IF(OR(F6="",C6="Deleted"),"",IF(F6<>A6,"Yes","No")) -> No | H6: =IF(C6="Deleted","",A6-I6) -> 5 | I6: =N(I5)+IF(C6="Deleted",1,0) -> 0
A7: 6 | B7: GJ_65_B | C7: Untouched | D7: 6 | E7: GJ_65_B | F7: 6 | G7: =IF(OR(F7="",C7="Deleted"),"",IF(F7<>A7,"Yes","No")) -> No | H7: =IF(C7="Deleted","",A7-I7) -> 6 | I7: =N(I6)+IF(C7="Deleted",1,0) -> 0
A8: 7 | B8: GJ_234_A | C8: Untouched | D8: 7 | E8: GJ_234_A | F8: 7 | G8: =IF(OR(F8="",C8="Deleted"),"",IF(F8<>A8,"Yes","No")) -> No | H8: =IF(C8="Deleted","",A8-I8) -> 7 | I8: =N(I7)+IF(C8="Deleted",1,0) -> 0
A9: 8 | B9: GJ_234_B | C9: Untouched | D9: 8 | E9: GJ_234_B | F9: 8 | G9: =IF(OR(F9="",C9="Deleted"),"",IF(F9<>A9,"Yes","No")) -> No | H9: =IF(C9="Deleted","",A9-I9) -> 8 | I9: =N(I8)+IF(C9="Deleted",1,0) -> 0
A10: 9 | B10: G_250-029_A | C10: Untouched | D10: 9 | E10: G_250-029_A | F10: 9 | G10: =IF(OR(F10="",C10="Deleted"),"",IF(F10<>A10,"Yes","No")) -> No | H10: =IF(C10="Deleted","",A10-I10) -> 9 | I10: =N(I9)+IF(C10="Deleted",1,0) -> 0
A11: 10 | B11: G_250-029_B | C11: Untouched | D11: 10 | E11: G_250-029_B | F11: 10 | G11: =IF(OR(F11="",C11="Deleted"),"",IF(F11<>A11,"Yes","No")) -> No | H11: =IF(C11="Deleted","",A11-I11) -> 10 | I11: =N(I10)+IF(C11="Deleted",1,0) -> 0
A12: 11 | B12: G_193-027_A | C12: Untouched | D12: 11 | E12: G_193-027_A | F12: 11 | G12: =IF(OR(F12="",C12="Deleted"),"",IF(F12<>A12,"Yes","No")) -> No | H12: =IF(C12="Deleted","",A12-I12) -> 11 | I12: =N(I11)+IF(C12="Deleted",1,0) -> 0
A13: 12 | B13: G_193-027_B | C13: Untouched | D13: 12 | E13: G_193-027_B | F13: 12 | G13: =IF(OR(F13="",C13="Deleted"),"",IF(F13<>A13,"Yes","No")) -> No | H13: =IF(C13="Deleted","",A13-I13) -> 12 | I13: =N(I12)+IF(C13="Deleted",1,0) -> 0
... A27: 26 | B27: TIC24397947_B | C27: Untouched | D27: 26 | E27: TIC24397947_B | F27: 26 | G27: =IF(OR(F27="",C27="Deleted"),"",IF(F27<>A27,"Yes","No")) -> No | H27: =IF(C27="Deleted","",A27-I27) -> 26 | I27: =N(I26)+IF(C27="Deleted",1,0) -> 0
A28: 27 | B28: HD4875_A | C28: Replaced | D28: 27 | E28: TIC28051929_A | G28: =IF(OR(F28="",C28="Deleted"),"",IF(F28<>A28,"Yes","No")) | H28: =IF(C28="Deleted","",A28-I28) -> 27 | I28: =N(I27)+IF(C28="Deleted",1,0) -> 0
A29: 28 | B29: HD4875_B | C29: Replaced | D29: 28 | E29: TIC28051929_B | G29: =IF(OR(F29="",C29="Deleted"),"",IF(F29<>A29,"Yes","No")) | H29: =IF(C29="Deleted","",A29-I29) -> 28 | I29: =N(I28)+IF(C29="Deleted",1,0) -> 0
A30: 29 | B30: TIC37606218__A | C30: Deleted | D30: 29 | E30: TIC37606218__A | F30: 29 | G30: =IF(OR(F30="",C30="Deleted"),"",IF(F30<>A30,"Yes","No")) | H30: =IF(C30="Deleted","",A30-I30) | I30: =N(I29)+IF(C30="Deleted",1,0) -> 1
A31: 30 | B31: TIC37606218__B | C31: Deleted | D31: 30 | E31: TIC37606218__B | F31: 30 | G31: =IF(OR(F31="",C31="Deleted"),"",IF(F31<>A31,"Yes","No")) | H31: =IF(C31="Deleted","",A31-I31) | I31: =N(I30)+IF(C31="Deleted",1,0) -> 2
A32: 31 | B32: TIC89045042_A | C32: Untouched | D32: 31 | E32: TIC89045042_A | F32: 31 | G32: =IF(OR(F32="",C32="Deleted"),"",IF(F32<>A32,"Yes","No")) -> No | H32: =IF(C32="Deleted","",A32-I32) -> 29 | I32: =N(I31)+IF(C32="Deleted",1,0) -> 2
A33: 32 | B33: TIC89045042_B | C33: Untouched | D33: 32 | E33: TIC89045042_B | F33: 32 | G33: =IF(OR(F33="",C33="Deleted"),"",IF(F33<>A33,"Yes","No")) -> No | H33: =IF(C33="Deleted","",A33-I33) -> 30 | I33: =N(I32)+IF(C33="Deleted",1,0) -> 2
A34: 33 | B34: TIC126700850_A | C34: Untouched | D34: 33 | E34: TIC126700850_A | F34: 33 | G34: =IF(OR(F34="",C34="Deleted"),"",IF(F34<>A34,"Yes","No")) -> No | H34: =IF(C34="Deleted","",A34-I34) -> 31 | I34: =N(I33)+IF(C34="Deleted",1,0) -> 2
A35: 34 | B35: TIC126700850_B | C35: Untouched | D35: 34 | E35: TIC126700850_B | F35: 34 | G35: =IF(OR(F35="",C35="Deleted"),"",IF(F35<>A35,"Yes","No")) -> No | H35: =IF(C35="Deleted","",A35-I35) -> 32 | I35: =N(I34)+IF(C35="Deleted",1,0) -> 2
A36: 35 | B36: TIC138857475_A | C36: Deleted | D36: 35 | E36: TIC138857475_A | F36: 35 | G36: =IF(OR(F36="",C36="Deleted"),"",IF(F36<>A36,"Yes","No")) | H36: =IF(C36="Deleted","",A36-I36) | I36: =N(I35)+IF(C36="Deleted",1,0) -> 3
A37: 36 | B37: TIC138857475_B | C37: Deleted | D37: 36 | E37: TIC138857475_B | F37: 36 | G37: =IF(OR(F37="",C37="Deleted"),"",IF(F37<>A37,"Yes","No")) | H37: =IF(C37="Deleted","",A37-I37) | I37: =N(I36)+IF(C37="Deleted",1,0) -> 4
A38: 37 | B38: TYC_8547-22-1_A | C38: Replaced | D38: 37 | E38: TIC278683641_A | G38: =IF(OR(F38="",C38="Deleted"),"",IF(F38<>A38,"Yes","No")) | H38: =IF(C38="Deleted","",A38-I38) -> 33 | I38: =N(I37)+IF(C38="Deleted",1,0) -> 4
A39: 38 | B39: TYC_8547-22-1_B | C39: Replaced | D39: 38 | E39: TIC278683641_B | G39: =IF(OR(F39="",C39="Deleted"),"",IF(F39<>A39,"Yes","No")) | H39: =IF(C39="Deleted","",A39-I39) -> 34 | I39: =N(I38)+IF(C39="Deleted",1,0) -> 4
A40: 39 | B40: TIC287841093_A | C40: Deleted | D40: 39 | E40: TIC287841093_A | F40: 39 | G40: =IF(OR(F40="",C40="Deleted"),"",IF(F40<>A40,"Yes","No")) | H40: =IF(C40="Deleted","",A40-I40) | I40: =N(I39)+IF(C40="Deleted",1,0) -> 5
A41: 40 | B41: TIC287841093_B | C41: Deleted | D41: 40 | E41: TIC287841093_B | F41: 40 | G41: =IF(OR(F41="",C41="Deleted"),"",IF(F41<>A41,"Yes","No")) | H41: =IF(C41="Deleted","",A41-I41) | I41: =N(I40)+IF(C41="Deleted",1,0) -> 6
A42: 41 | B42: KIC9656397_A | C42: Untouched | D42: 41 | E42: KIC9656397_A | F42: 41 | G42: =IF(OR(F42="",C42="Deleted"),"",IF(F42<>A42,"Yes","No")) -> No | H42: =IF(C42="Deleted","",A42-I42) -> 35 | I42: =N(I41)+IF(C42="Deleted",1,0) -> 6
A43: 42 | B43: KIC9656397_B | C43: Untouched | D43: 42 | E43: KIC9656397_B | F43: 42 | G43: =IF(OR(F43="",C43="Deleted"),"",IF(F43<>A43,"Yes","No")) -> No | H43: =IF(C43="Deleted","",A43-I43) -> 36 | I43: =N(I42)+IF(C43="Deleted",1,0) -> 6
A44: 43 | B44: LL_Aqr_A | C44: Replaced | D44: 43 | E44: LL_Aqr_A | F44: 43 | G44: =IF(OR(F44="",C44="Deleted"),"",IF(F44<>A44,"Yes","No")) -> No | H44: =IF(C44="Deleted","",A44-I44) -> 37 | I44: =N(I43)+IF(C44="Deleted",1,0) -> 6
A45: 44 | B45: LL_Aqr_B | C45: Replaced | D45: 44 | E45: LL_Aqr_B | F45: 44 | G45: =IF(OR(F45="",C45="Deleted"),"",IF(F45<>A45,"Yes","No")) -> No | H45: =IF(C45="Deleted","",A45-I45) -> 38 | I45: =N(I44)+IF(C45="Deleted",1,0) -> 6
A46: 45 | B46: V570_Per_A | C46: Untouched | D46: 45 | E46: V570_Per_A | F46: 45 | G46: =IF(OR(F46="",C46="Deleted"),"",IF(F46<>A46,"Yes","No")) -> No | H46: =IF(C46="Deleted","",A46-I46) -> 39 | I46: =N(I45)+IF(C46="Deleted",1,0) -> 6
A47: 46 | B47: V570_Per_B | C47: Untouched | D47: 46 | E47: V570_Per_B | F47: 46 | G47: =IF(OR(F47="",C47="Deleted"),"",IF(F47<>A47,"Yes","No")) -> No | H47: =IF(C47="Deleted","",A47-I47) -> 40 | I47: =N(I46)+IF(C47="Deleted",1,0) -> 6
A48: 47 | B48: TIC322208686_A | C48: Untouched | D48: 47 | E48: TIC322208686_A | F48: 47 | G48: =IF(OR(F48="",C48="Deleted"),"",IF(F48<>A48,"Yes","No")) -> No | H48: =IF(C48="Deleted","",A48-I48) -> 41 | I48: =N(I47)+IF(C48="Deleted",1,0) -> 6
A49: 48 | B49: TIC322208686_B | C49: Untouched | D49: 48 | E49: TIC322208686_B | F49: 48 | G49: =IF(OR(F49="",C49="Deleted"),"",IF(F49<>A49,"Yes","No")) -> No | H49: =IF(C49="Deleted","",A49-I49) -> 42 | I49: =N(I48)+IF(C49="Deleted",1,0) -> 6
A50: 49 | B50: TYC_4535-148-1_A | C50: Replaced | D50: 49 | E50: BEPOP-3_A | G50: =IF(OR(F50="",C50="Deleted"),"",IF(F50<>A50,"Yes","No")) | H50: =IF(C50="Deleted","",A50-I50) -> 43 | I50: =N(I49)+IF(C50="Deleted",1,0) -> 6
A51: 50 | B51: TYC_4535-148-1_B | C51: Replaced | D51: 50 | E51: BEPOP-3_B | G51: =IF(OR(F51="",C51="Deleted"),"",IF(F51<>A51,"Yes","No")) | H51: =IF(C51="Deleted","",A51-I51) -> 44 | I51: =N(I50)+IF(C51="Deleted",1,0) -> 6
A52: 51 | B52: TIC189069314_A | C52: Untouched | D52: 51 | E52: TIC189069314_A | F52: 51 | G52: =IF(OR(F52="",C52="Deleted"),"",IF(F52<>A52,"Yes","No")) -> No | H52: =IF(C52="Deleted","",A52-I52) -> 45 | I52: =N(I51)+IF(C52="Deleted",1,0) -> 6
A53: 52 | B53: TIC189069314_B | C53: Untouched | D53: 52 | E53: TIC189069314_B | F53: 52 | G53: =IF(OR(F53="",C53="Deleted"),"",IF(F53<>A53,"Yes","No")) -> No | H53: =IF(C53="Deleted","",A53-I53) -> 46 | I53: =N(I52)+IF(C53="Deleted",1,0) -> 6
...
